Workbook
Name Module1.PrintMacro: [1]!Module1.PrintMacro
Name Module1.PrintMacro: [1]!Module1.PrintMacro
Name MultiSort: [2]!MultiSort
Name MultiSort: [2]!MultiSort
Name PrintMacro: [3]!PrintMacro
Name PrintMacro: [3]!PrintMacro
Name ValidateChangeInDialogSelection: SFG_DDS!ValidateChangeInDialogSelection
Name ValidateChangeInDialogSelection: 'SFG_DDS 24'!ValidateChangeInDialogSelection
Name ValidateChangeInDialogSelection: [4]!ValidateChangeInDialogSelection

Sheet Inbound_Monitor
A1: Auto | B1: Ursprüngliches geplantes Ankunftsdatum E-Mail | C1: Lieferdatum Update | D1: Auto | E1: Ist Datum (Tatsächliche Anlieferung) | F1: Reihenfolge pro Ist Datum | G1: Auto | H1: SCI | I1: Source Location/ Spedition | J1: Purchase Order/Sales Order Nummer | K1: Anzahl Pal./Box | L1: Category | M1: Status | N1: Echtzeit vom Büro | O1: Echtzeit vom Büro | P1: Echtzeit vom Büro | Q1: Echtzeit vom Büro | R1: SAP Buchung erfolgt? | S1: Bemerkungen | T1: Dauer der Klärung | U1: Probleme | V1: Auto | W1: Auto | X1: Auto | Y1: Auto
A2: KW IB Plan | D2: KW IB Ist | G2: Timeslot getroffen (auto) | N2: Ankunft Office | O2: Entladung gestartet | P2: Entladung beendet | Q2: Unloaded at Bayreuth (Documents finished) | V2: Wartezeit bis Entladebeginn | W2: Entladezeit | X2: Gesamtzeit 1 | Y2: Gesamtzeit 2
A3: nn | B3: dd.mm.yy | C3: dd.mm.yy | D3: nn | E3: dd.mm.yy | G3: Ja/Nein | H3: 1000xx | I3: Text | J3: No. | L3: Auswahl | M3: Auswahl | N3: hh:mm | O3: hh:mm | P3: hh:mm | Q3: hh:mm | R3: Yes / No | S3: Freitext | T3: Datum | U3: Grund | V3: hh:mm | W3: hh:mm | X3: hh:mm | Y3: hh:mm
A4: =IF(B4="","",WEEKNUM(B4,21)) -> 50 | B4: 45275 | C4: 45303 | D4: =IF(E4="","",WEEKNUM(E4,21)) -> 2 | E4: 45303 | G4: =IF(E4="","",IF(E4=B4,"Ja","Nein")) -> Nein | H4: 1000449201 | I4: Augustow | J4: 4702114236 | K4: 94 | L4: STEM | M4: Entladen | N4: 0.27430556 | O4: 0.28819444 | P4: 0.30555556 | Q4: 0.30555556 | V4: =IF(N4="","",IF(O4="","",O4-N4)) -> 0.013888889 | W4: =IF(O4="","",IF(P4="","",P4-O4)) -> 0.017361111 | X4: =IF(P4="","",IF(N4="","",P4-N4)) -> 0.03125 | Y4: =IF(N4="","",IF(Q4="","",Q4-N4)) -> 0.03125
A5: =IF(B5="","",WEEKNUM(B5,21)) -> 51 | B5: 45278 | C5: 45307 | D5: =IF(E5="","",WEEKNUM(E5,21)) -> 3 | E5: 45308 | F5: 2 | G5: =IF(E5="","",IF(E5=B5,"Ja","Nein")) -> Nein | H5: 1000451102 | I5: Kroatien | J5: 4601391876 | K5: 100 | L5: Leaf | M5: Entladen | N5: 0.34097222 | O5: 0.45833333 | P5: 0.48888889 | Q5: 0.49583333 | R5: Yes | S5: Fahrer kam zu spät, wird am 17.01. abgeladen | V5: =IF(N5="","",IF(O5="","",O5-N5)) -> 0.11736111 | W5: =IF(O5="","",IF(P5="","",P5-O5)) -> 0.030555556 | X5: =IF(P5="","",IF(N5="","",P5-N5)) -> 0.14791667 | Y5: =IF(N5="","",IF(Q5="","",Q5-N5)) -> 0.15486111
A6: =IF(B6="","",WEEKNUM(B6,21)) -> 2 | B6: 45300 | D6: =IF(E6="","",WEEKNUM(E6,21)) -> 2 | E6: 45300 | G6: =IF(E6="","",IF(E6=B6,"Ja","Nein")) -> Ja | I6: Türkei | J6: 158807_1 | K6: 50 | L6: IBC | M6: Entladen | N6: 0.36666667 | O6: 0.39583333 | P6: 0.41666667 | Q6: 0.41666667 | V6: =IF(N6="","",IF(O6="","",O6-N6)) -> 0.029166667 | W6: =IF(O6="","",IF(P6="","",P6-O6)) -> 0.020833333 | X6: =IF(P6="","",IF(N6="","",P6-N6)) -> 0.05 | Y6: =IF(N6="","",IF(Q6="","",Q6-N6)) -> 0.05
A7: =IF(B7="","",WEEKNUM(B7,21)) -> 2 | B7: 45300 | D7: =IF(E7="","",WEEKNUM(E7,21)) -> 2 | E7: 45300 | G7: =IF(E7="","",IF(E7=B7,"Ja","Nein")) -> Ja | I7: Türkei | J7: 158807_2 | K7: 50 | L7: IBC | M7: Entladen | N7: 0.41458333 | O7: 0.42361111 | P7: 0.44791667 | Q7: 0.44791667 | V7: =IF(N7="","",IF(O7="","",O7-N7)) -> 0.0090277778 | W7: =IF(O7="","",IF(P7="","",P7-O7)) -> 0.024305556 | X7: =IF(P7="","",IF(N7="","",P7-N7)) -> 0.033333333 | Y7: =IF(N7="","",IF(Q7="","",Q7-N7)) -> 0.033333333
A8: =IF(B8="","",WEEKNUM(B8,21)) -> 2 | B8: 45300 | D8: =IF(E8="","",WEEKNUM(E8,21)) -> 2 | E8: 45300 | G8: =IF(E8="","",IF(E8=B8,"Ja","Nein")) -> Ja | I8: Türkei | J8: 158807_3 | K8: 50 | L8: IBC | M8: Entladen | N8: 0.50486111 | O8: 0.52083333 | P8: 0.54166667 | Q8: 0.54166667 | V8: =IF(N8="","",IF(O8="","",O8-N8)) -> 0.015972222 | W8: =IF(O8="","",IF(P8="","",P8-O8)) -> 0.020833333 | X8: =IF(P8="","",IF(N8="","",P8-N8)) -> 0.036805556 | Y8: =IF(N8="","",IF(Q8="","",Q8-N8)) -> 0.036805556
A9: =IF(B9="","",WEEKNUM(B9,21)) -> 2 | B9: 45301 | D9: =IF(E9="","",WEEKNUM(E9,21)) -> 2 | E9: 45301 | F9: 1 | G9: =IF(E9="","",IF(E9=B9,"Ja","Nein")) -> Ja | H9: 1000447751 | I9: Antwerpen | J9: 125978 | K9: 105 | L9: Leaf | M9: Entladen | N9: 0.37222222 | O9: 0.3875 | P9: 0.40902778 | Q9: 0.45833333 | R9: Yes | S9: muss auch verladen werden | V9: =IF(N9="","",IF(O9="","",O9-N9)) -> 0.015277778 | W9: =IF(O9="","",IF(P9="","",P9-O9)) -> 0.021527778 | X9: =IF(P9="","",IF(N9="","",P9-N9)) -> 0.036805556 | Y9: =IF(N9="","",IF(Q9="","",Q9-N9)) -> 0.086111111
A10: =IF(B10="","",WEEKNUM(B10,21)) -> 2 | B10: 45301 | D10: =IF(E10="","",WEEKNUM(E10,21)) -> 2 | E10: 45301 | F10: 2 | G10: =IF(E10="","",IF(E10=B10,"Ja","Nein")) -> Ja | H10: 1000447754 | I10: Antwerpen | J10: 125981 | K10: 105 | L10: Leaf | M10: Entladen | N10: 0.3875 | O10: 0.44444444 | P10: 0.47777778 | Q10: 0.59444444 | R10: Yes | S10: muss auch verladen werden | T10: 45306 | U10: Für T1-Ware existiert keine PO, da Preise fehlen. Zollanmeldung und WE-Buchung kann erst erfolgen, wenn Inbound vorhanden. | V10: =IF(N10="","",IF(O10="","",O10-N10)) -> 0.056944444 | W10: =IF(O10="","",IF(P10="","",P10-O10)) -> 0.033333333 | X10: =IF(P10="","",IF(N10="","",P10-N10)) -> 0.090277778 | Y10: =IF(N10="","",IF(Q10="","",Q10-N10)) -> 0.20694444
A11: =IF(B11="","",WEEKNUM(B11,21)) -> 2 | B11: 45301 | C11: 45308 | D11: =IF(E11="","",WEEKNUM(E11,21)) -> 3 | E11: 45309 | F11: 2 | G11: =IF(E11="","",IF(E11=B11,"Ja","Nein")) -> Nein | H11: 1000451497 | I11: Kroatien | J11: 4601387585 | K11: 108 | L11: Leaf | M11: Entladen | N11: 0.45277778 | O11: 0.48611111 | P11: 0.51388889 | Q11: 0.52291667 | R11: Yes | S11: Kapazität von 6 St. erreicht, wird am 18.01. abgeladen | V11: =IF(N11="","",IF(O11="","",O11-N11)) -> 0.033333333 | W11: =IF(O11="","",IF(P11="","",P11-O11)) -> 0.027777778 | X11: =IF(P11="","",IF(N11="","",P11-N11)) -> 0.061111111 | Y11: =IF(N11="","",IF(Q11="","",Q11-N11)) -> 0.070138889
A12: =IF(B12="","",WEEKNUM(B12,21)) -> 2 | B12: 45301 | D12: =IF(E12="","",WEEKNUM(E12,21)) -> 2 | E12: 45301 | F12: 3 | G12: =IF(E12="","",IF(E12=B12,"Ja","Nein")) -> Ja | H12: 1000449464 | I12: Kroatien | J12: 4601387586 | K12: 108 | L12: Leaf | M12: Entladen | N12: 0.52222222 | O12: 0.53472222 | P12: 0.55555556 | Q12: 0.56736111 | R12: Yes | V12: =IF(N12="","",IF(O12="","",O12-N12)) -> 0.0125 | W12: =IF(O12="","",IF(P12="","",P12-O12)) -> 0.020833333 | X12: =IF(P12="","",IF(N12="","",P12-N12)) -> 0.033333333 | Y12: =IF(N12="","",IF(Q12="","",Q12-N12)) -> 0.045138889
A13: =IF(B13="","",WEEKNUM(B13,21)) -> 2 | B13: 45301 | D13: =IF(E13="","",WEEKNUM(E13,21)) -> 2 | E13: 45301 | G13: =IF(E13="","",IF(E13=B13,"Ja","Nein")) -> Ja | I13: Fehrbellin | J13: 4500545501 | K13: 32 | L13: Rohware | M13: Entladen | N13: 0.31805556 | O13: 0.33333333 | P13: 0.375 | Q13: 0.375 | V13: =IF(N13="","",IF(O13="","",O13-N13)) -> 0.015277778 | W13: =IF(O13="","",IF(P13="","",P13-O13)) -> 0.041666667 | X13: =IF(P13="","",IF(N13="","",P13-N13)) -> 0.056944444 | Y13: =IF(N13="","",IF(Q13="","",Q13-N13)) -> 0.056944444
A14: =IF(B14="","",WEEKNUM(B14,21)) -> 2 | B14: 45302 | D14: =IF(E14="","",WEEKNUM(E14,21)) -> 2 | E14: 45303 | F14: 1 | G14: =IF(E14="","",IF(E14=B14,"Ja","Nein")) -> Nein | H14: 1000450230 | I14: Kroatien | J14: 4601395602 | K14: 105 | L14: Leaf | M14: Entladen | N14: 0.31527778 | O14: 0.33333333 | P14: 0.36458333 | Q14: 0.37777778 | R14: Yes | V14: =IF(N14="","",IF(O14="","",O14-N14)) -> 0.018055556 | W14: =IF(O14="","",IF(P14="","",P14-O14)) -> 0.03125 | X14: =IF(P14="","",IF(N14="","",P14-N14)) -> 0.049305556 | Y14: =IF(N14="","",IF(Q14="","",Q14-N14)) -> 0.0625
A15: =IF(B15="","",WEEKNUM(B15,21)) -> 2 | B15: 45303 | D15: =IF(E15="","",WEEKNUM(E15,21)) -> 3 | E15: 45306 | G15: =IF(E15="","",IF(E15=B15,"Ja","Nein")) -> Nein | H15: 1000451166 | I15: Ploiesti | K15: 66 | L15: IBC | M15: Entladen | N15: 0.34236111 | O15: 0.36111111 | P15: 0.37847222 | Q15: 0.37847222 | V15: =IF(N15="","",IF(O15="","",O15-N15)) -> 0.01875 | W15: =IF(O15="","",IF(P15="","",P15-O15)) -> 0.017361111 | X15: =IF(P15="","",IF(N15="","",P15-N15)) -> 0.036111111 | Y15: =IF(N15="","",IF(Q15="","",Q15-N15)) -> 0.036111111
A16: =IF(B16="","",WEEKNUM(B16,21)) -> 3 | B16: 45306 | C16: 45308 | D16: =IF(E16="","",WEEKNUM(E16,21)) -> 3 | E16: 45309 | F16: 1 | G16: =IF(E16="","",IF(E16=B16,"Ja","Nein")) -> Nein | H16: 1000451783 | I16: Antwerpen | J16: 125979 | K16: 105 | L16: Leaf | M16: Entladen | N16: 0.30833333 | O16: 0.31666667 | P16: 0.34583333 | Q16: 0.43125 | R16: Yes | S16: docs issue: T1 fehlt; Kapazität von 6 St. erreicht, wird am 18.01. abgeladen; muss auch verladen werden | V16: =IF(N16="","",IF(O16="","",O16-N16)) -> 0.0083333333 | W16: =IF(O16="","",IF(P16="","",P16-O16)) -> 0.029166667 | X16: =IF(P16="","",IF(N16="","",P16-N16)) -> 0.0375 | Y16: =IF(N16="","",IF(Q16="","",Q16-N16)) -> 0.12291667
A17: =IF(B17="","",WEEKNUM(B17,21)) -> 3 | B17: 45306 | C17: 45308 | D17: =IF(E17="","",WEEKNUM(E17,21)) -> 3 | E17: 45308 | F17: 4 | G17: =IF(E17="","",IF(E17=B17,"Ja","Nein")) -> Nein | H17: 1000447753 | I17: Antwerpen | J17: 125980 | K17: 105 | L17: Leaf | M17: Entladen | N17: 0.37361111 | O17: 0.41388889 | P17: 0.44027778 | Q17: 0.50069444 | R17: Yes | S17: muss auch verladen werden | V17: =IF(N17="","",IF(O17="","",O17-N17)) -> 0.040277778 | W17: =IF(O17="","",IF(P17="","",P17-O17)) -> 0.026388889 | X17: =IF(P17="","",IF(N17="","",P17-N17)) -> 0.066666667 | Y17: =IF(N17="","",IF(Q17="","",Q17-N17)) -> 0.12708333
A18: =IF(B18="","",WEEKNUM(B18,21)) -> 3 | B18: 45307 | C18: 45307 | D18: =IF(E18="","",WEEKNUM(E18,21)) -> 3 | E18: 45307 | F18: 2 | G18: =IF(E18="","",IF(E18=B18,"Ja","Nein")) -> Ja | H18: 1000447746 | I18: Antwerpen | J18: 125973 | K18: 105 | L18: Leaf | M18: Entladen | N18: 0.39652778 | O18: 0.41458333 | P18: 0.44027778 | Q18: 0.53402778 | R18: Yes | S18: docs issue: keine Dokumente vorab erhalten; muss auch verladen werden | V18: =IF(N18="","",IF(O18="","",O18-N18)) -> 0.018055556 | W18: =IF(O18="","",IF(P18="","",P18-O18)) -> 0.025694444 | X18: =IF(P18="","",IF(N18="","",P18-N18)) -> 0.04375 | Y18: =IF(N18="","",IF(Q18="","",Q18-N18)) -> 0.1375
A19: =IF(B19="","",WEEKNUM(B19,21)) -> 3 | B19: 45307 | C19: 45307 | D19: =IF(E19="","",WEEKNUM(E19,21)) -> 3 | E19: 45307 | F19: 1 | G19: =IF(E19="","",IF(E19=B19,"Ja","Nein")) -> Ja | H19: 1000447748 | I19: Antwerpen | J19: 125975 | K19: 105 | L19: Leaf | M19: Entladen | N19: 0.30069444 | O19: 0.34305556 | P19: 0.37291667 | Q19: 0.45347222 | R19: Yes | S19: docs issue: keine Dokumente vorab erhalten; muss auch verladen werden | V19: =IF(N19="","",IF(O19="","",O19-N19)) -> 0.042361111 | W19: =IF(O19="","",IF(P19="","",P19-O19)) -> 0.029861111 | X19: =IF(P19="","",IF(N19="","",P19-N19)) -> 0.072222222 | Y19: =IF(N19="","",IF(Q19="","",Q19-N19)) -> 0.15277778
A20: =IF(B20="","",WEEKNUM(B20,21)) -> 3 | B20: 45307 | D20: =IF(E20="","",WEEKNUM(E20,21)) -> 3 | E20: 45308 | F20: 6 | G20: =IF(E20="","",IF(E20=B20,"Ja","Nein")) -> Nein | H20: 1000451103 | I20: Kroatien | J20: 4601387587 | K20: 100 | L20: Leaf | M20: Entladen | N20: 0.39652778 | O20: 0.50347222 | P20: 0.56805556 | Q20: 0.77083333 | R20: Yes | S20: muss auch verladen werden | V20: =IF(N20="","",IF(O20="","",O20-N20)) -> 0.10694444 | W20: =IF(O20="","",IF(P20="","",P20-O20)) -> 0.064583333 | X20: =IF(P20="","",IF(N20="","",P20-N20)) -> 0.17152778 | Y20: =IF(N20="","",IF(Q20="","",Q20-N20)) -> 0.37430556 | Z20: 38
A21: =IF(B21="","",WEEKNUM(B21,21)) -> 3 | B21: 45307 | D21: =IF(E21="","",WEEKNUM(E21,21)) -> 3 | E21: 45307 | F21: 3 | G21: =IF(E21="","",IF(E21=B21,"Ja","Nein")) -> Ja | H21: 1000451786 | I21: Kroatien | J21: 4702155228 | K21: 107 | L21: Leaf | M21: Entladen | N21: 0.48541667 | O21: 0.54791667 | P21: 0.57222222 | Q21: 0.58402778 | R21: Yes | S21: docs issue: CoA für Material 1027840X fehlt, kommt per Kurier | V21: =IF(N21="","",IF(O21="","",O21-N21)) -> 0.0625 | W21: =IF(O21="","",IF(P21="","",P21-O21)) -> 0.024305556 | X21: =IF(P21="","",IF(N21="","",P21-N21)) -> 0.086805556 | Y21: =IF(N21="","",IF(Q21="","",Q21-N21)) -> 0.098611111
A22: =IF(B22="","",WEEKNUM(B22,21)) -> 3 | B22: 45308 | C22: 45308 | D22: =IF(E22="","",WEEKNUM(E22,21)) -> 3 | E22: 45308 | F22: 5 | G22: =IF(E22="","",IF(E22=B22,"Ja","Nein")) -> Ja | H22: 1000447744 | I22: Antwerpen | J22: 125971 | K22: 102 | L22: Leaf | M22: Entladen | N22: 0.38541667 | O22: 0.49652778 | P22: 0.52638889 | Q22: 0.53125 | R22: Yes | V22: =IF(N22="","",IF(O22="","",O22-N22)) -> 0.11111111 | W22: =IF(O22="","",IF(P22="","",P22-O22)) -> 0.029861111 | X22: =IF(P22="","",IF(N22="","",P22-N22)) -> 0.14097222 | Y22: =IF(N22="","",IF(Q22="","",Q22-N22)) -> 0.14583333
A23: =IF(B23="","",WEEKNUM(B23,21)) -> 3 | B23: 45308 | C23: 45308 | D23: =IF(E23="","",WEEKNUM(E23,21)) -> 3 | E23: 45308 | F23: 1 | G23: =IF(E23="","",IF(E23=B23,"Ja","Nein")) -> Ja | H23: 1000447745 | I23: Antwerpen | J23: 125972 | K23: 94 | L23: Leaf | M23: Entladen | N23: 0.32569444 | O23: 0.33888889 | P23: 0.36458333 | Q23: 0.37222222 | R23: Yes | S23: docs issue: keine Dokumente vorab erhalten | V23: =IF(N23="","",IF(O23="","",O23-N23)) -> 0.013194444 | W23: =IF(O23="","",IF(P23="","",P23-O23)) -> 0.025694444 | X23: =IF(P23="","",IF(N23="","",P23-N23)) -> 0.038888889 | Y23: =IF(N23="","",IF(Q23="","",Q23-N23)) -> 0.046527778
A24: =IF(B24="","",WEEKNUM(B24,21)) -> 3 | B24: 45308 | C24: 45308 | D24: =IF(E24="","",WEEKNUM(E24,21)) -> 3 | E24: 45308 | F24: 3 | G24: =IF(E24="","",IF(E24=B24,"Ja","Nein")) -> Ja | H24: 1000447747 | I24: Antwerpen | J24: 125974 | K24: 105 | L24: Leaf | M24: Entladen | N24: 0.34652778 | O24: 0.37361111 | P24: 0.40069444 | Q24: 0.48055556 | R24: Yes | S24: muss auch verladen werden | V24: =IF(N24="","",IF(O24="","",O24-N24)) -> 0.027083333 | W24: =IF(O24="","",IF(P24="","",P24-O24)) -> 0.027083333 | X24: =IF(P24="","",IF(N24="","",P24-N24)) -> 0.054166667 | Y24: =IF(N24="","",IF(Q24="","",Q24-N24)) -> 0.13402778
A25: =IF(B25="","",WEEKNUM(B25,21)) -> 3 | B25: 45308 | C25: 45328 | D25: =IF(E25="","",WEEKNUM(E25,21)) -> 6 | E25: 45328 | F25: 3 | G25: =IF(E25="","",IF(E25=B25,"Ja","Nein")) -> Nein | H25: 1000456716 | I25: Kroatien | J25: 4601387588 | K25: 108 | L25: Leaf | M25: Entladen | N25: 0.37916667 | O25: 0.39583333 | P25: 0.42222222 | Q25: 0.43333333 | R25: Yes | V25: =IF(N25="","",IF(O25="","",O25-N25)) -> 0.016666667 | W25: =IF(O25="","",IF(P25="","",P25-O25)) -> 0.026388889 | X25: =IF(P25="","",IF(N25="","",P25-N25)) -> 0.043055556 | Y25: =IF(N25="","",IF(Q25="","",Q25-N25)) -> 0.054166667
A26: =IF(B26="","",WEEKNUM(B26,21)) -> 3 | B26: 45308 | E26: 45308 | G26: =IF(E26="","",IF(E26=B26,"Ja","Nein")) -> Ja | I26: Verbio | J26: 4500551034 | K26: 12 | L26: Rohware | M26: Entladen | N26: 0.51944444 | O26: 0.54166667 | P26: 0.55208333 | Q26: 0.55208333
A27: =IF(B27="","",WEEKNUM(B27,21)) -> 3 | B27: 45309 | C27: 45309 | D27: =IF(E27="","",WEEKNUM(E27,21)) -> 3 | E27: 45310 | F27: 2 | G27: =IF(E27="","",IF(E27=B27,"Ja","Nein")) -> Nein | H27: 1000447750 | I27: Antwerpen | J27: 125977 | K27: 105 | L27: Leaf | M27: Entladen | N27: 0.35555556 | O27: 0.36805556 | P27: 0.39583333 | Q27: 0.40694444 | R27: Yes | V27: =IF(N27="","",IF(O27="","",O27-N27)) -> 0.0125 | W27: =IF(O27="","",IF(P27="","",P27-O27)) -> 0.027777778 | X27: =IF(P27="","",IF(N27="","",P27-N27)) -> 0.040277778 | Y27: =IF(N27="","",IF(Q27="","",Q27-N27)) -> 0.051388889
A28: =IF(B28="","",WEEKNUM(B28,21)) -> 3 | B28: 45309 | C28: 45309 | D28: =IF(E28="","",WEEKNUM(E28,21)) -> 3 | E28: 45310 | F28: 3 | G28: =IF(E28="","",IF(E28=B28,"Ja","Nein")) -> Nein | H28: 1000447755 | I28: Antwerpen | J28: 125982 | K28: 104 | L28: Leaf | M28: Entladen | N28: 0.39375 | O28: 0.43958333 | P28: 0.475 | Q28: 0.48263889 | R28: Yes | S28: Fahrer kam zu spät, wird am 19.01. abgeladen | V28: =IF(N28="","",IF(O28="","",O28-N28)) -> 0.045833333 | W28: =IF(O28="","",IF(P28="","",P28-O28)) -> 0.035416667 | X28: =IF(P28="","",IF(N28="","",P28-N28)) -> 0.08125 | Y28: =IF(N28="","",IF(Q28="","",Q28-N28)) -> 0.088888889
A29: =IF(B29="","",WEEKNUM(B29,21)) -> 3 | B29: 45310 | C29: 45310 | D29: =IF(E29="","",WEEKNUM(E29,21)) -> 3 | E29: 45310 | F29: 1 | G29: =IF(E29="","",IF(E29=B29,"Ja","Nein")) -> Ja | H29: 1000447749 | I29: Antwerpen | J29: 125976 | K29: 75 | L29: Leaf | M29: Entladen | N29: 0.28958333 | O29: 0.32708333 | P29: 0.35486111 | Q29: 0.36041667 | R29: Yes | V29: =IF(N29="","",IF(O29="","",O29-N29)) -> 0.0375 | W29: =IF(O29="","",IF(P29="","",P29-O29)) -> 0.027777778 | X29: =IF(P29="","",IF(N29="","",P29-N29)) -> 0.065277778 | Y29: =IF(N29="","",IF(Q29="","",Q29-N29)) -> 0.070833333
A30: =IF(B30="","",WEEKNUM(B30,21)) -> 3 | B30: 45310 | D30: =IF(E30="","",WEEKNUM(E30,21)) -> 3 | E30: 45310 | G30: =IF(E30="","",IF(E30=B30,"Ja","Nein")) -> Ja | I30: Schütz | J30: 5700591582 | K30: 93 | L30: IBC | M30: Entladen | O30: 0.3125 | P30: 0.34027778 | Q30: 0.34027778 | S30: ist über Pforte Nord reingefahren, hat sich bei mir nicht gemeldet
A31: =IF(B31="","",WEEKNUM(B31,21)) -> 4 | B31: 45313 | C31: 45313 | D31: =IF(E31="","",WEEKNUM(E31,21)) -> 4 | E31: 45313 | F31: 2 | G31: =IF(E31="","",IF(E31=B31,"Ja","Nein")) -> Ja | H31: 1000451801 | I31: Antwerpen | J31: 126170 | K31: 105 | L31: Leaf | M31: Entladen | N31: 0.32708333 | O31: 0.43680556 | P31: 0.46041667 | Q31: 0.46875 | R31: Yes | S31: docs issue: keine Dokumente vorab erhalten | V31: =IF(N31="","",IF(O31="","",O31-N31)) -> 0.10972222 | W31: =IF(O31="","",IF(P31="","",P31-O31)) -> 0.023611111 | X31: =IF(P31="","",IF(N31="","",P31-N31)) -> 0.13333333 | Y31: =IF(N31="","",IF(Q31="","",Q31-N31)) -> 0.14166667
A32: =IF(B32="","",WEEKNUM(B32,21)) -> 4 | B32: 45313 | C32: 45313 | D32: =IF(E32="","",WEEKNUM(E32,21)) -> 4 | E32: 45313 | F32: 1 | G32: =IF(E32="","",IF(E32=B32,"Ja","Nein")) -> Ja | H32: 1000452401 | I32: Antwerpen | J32: 126174 | K32: 105 | L32: Leaf | M32: Entladen | N32: 0.32083333 | O32: 0.38958333 | P32: 0.42291667 | Q32: 0.43402778 | R32: Yes | S32: docs issue: keine Dokumente vorab erhalten | V32: =IF(N32="","",IF(O32="","",O32-N32)) -> 0.06875 | W32: =IF(O32="","",IF(P32="","",P32-O32)) -> 0.033333333 | X32: =IF(P32="","",IF(N32="","",P32-N32)) -> 0.10208333 | Y32: =IF(N32="","",IF(Q32="","",Q32-N32)) -> 0.11319444
A33: =IF(B33="","",WEEKNUM(B33,21)) -> 4 | B33: 45313 | C33: 45315 | D33: =IF(E33="","",WEEKNUM(E33,21)) -> 4 | E33: 45315 | F33: 1 | G33: =IF(E33="","",IF(E33=B33,"Ja","Nein")) -> Nein | H33: 1000452402 | I33: Antwerpen | J33: 126177 | K33: 105 | L33: Leaf | M33: Entladen | N33: 0.40208333 | O33: 0.41111111 | P33: 0.43402778 | Q33: 0.44166667 | R33: Yes | V33: =IF(N33="","",IF(O33="","",O33-N33)) -> 0.0090277778 | W33: =IF(O33="","",IF(P33="","",P33-O33)) -> 0.022916667 | X33: =IF(P33="","",IF(N33="","",P33-N33)) -> 0.031944444 | Y33: =IF(N33="","",IF(Q33="","",Q33-N33)) -> 0.039583333
A34: =IF(B34="","",WEEKNUM(B34,21)) -> 4 | B34: 45314 | C34: 45314 | D34: =IF(E34="","",WEEKNUM(E34,21)) -> 4 | E34: 45314 | F34: 2 | G34: =IF(E34="","",IF(E34=B34,"Ja","Nein")) -> Ja | H34: 1000453615 | I34: Antwerpen | J34: 126173 | K34: 100 | L34: Leaf | M34: Entladen | N34: 0.39513889 | O34: 0.42638889 | P34: 0.44791667 | Q34: 0.51805556 | R34: Yes | S34: docs issue: keine Dokumente vorab erhalten; muss auch verladen werden | V34: =IF(N34="","",IF(O34="","",O34-N34)) -> 0.03125 | W34: =IF(O34="","",IF(P34="","",P34-O34)) -> 0.021527778 | X34: =IF(P34="","",IF(N34="","",P34-N34)) -> 0.052777778 | Y34: =IF(N34="","",IF(Q34="","",Q34-N34)) -> 0.12291667
A35: =IF(B35="","",WEEKNUM(B35,21)) -> 4 | B35: 45314 | C35: 45314 | D35: =IF(E35="","",WEEKNUM(E35,21)) -> 4 | E35: 45314 | F35: 1 | G35: =IF(E35="","",IF(E35=B35,"Ja","Nein")) -> Ja | H35: 1000453616 | I35: Antwerpen | J35: 126180 | K35: 105 | L35: Leaf | M35: Entladen | N35: 0.31666667 | O35: 0.34861111 | P35: 0.37777778 | Q35: 0.38680556 | R35: Yes | S35: docs issue: keine Dokumente vorab erhalten | V35: =IF(N35="","",IF(O35="","",O35-N35)) -> 0.031944444 | W35: =IF(O35="","",IF(P35="","",P35-O35)) -> 0.029166667 | X35: =IF(P35="","",IF(N35="","",P35-N35)) -> 0.061111111 | Y35: =IF(N35="","",IF(Q35="","",Q35-N35)) -> 0.070138889
A36: =IF(B36="","",WEEKNUM(B36,21)) -> 4 | B36: 45314 | D36: =IF(E36="","",WEEKNUM(E36,21)) -> 4 | E36: 45314 | F36: 3 | G36: =IF(E36="","",IF(E36=B36,"Ja","Nein")) -> Ja | H36: 1000453873 | I36: Kroatien | J36: 4601390251 | K36: 108 | L36: Leaf | M36: Entladen | N36: 0.42708333 | O36: 0.45833333 | P36: 0.48333333 | Q36: 0.49791667 | R36: Yes | V36: =IF(N36="","",IF(O36="","",O36-N36)) -> 0.03125 | W36: =IF(O36="","",IF(P36="","",P36-O36)) -> 0.025 | X36: =IF(P36="","",IF(N36="","",P36-N36)) -> 0.05625 | Y36: =IF(N36="","",IF(Q36="","",Q36-N36)) -> 0.070833333
A37: =IF(B37="","",WEEKNUM(B37,21)) -> 4 | B37: 45314 | C37: 45328 | D37: =IF(E37="","",WEEKNUM(E37,21)) -> 6 | E37: 45328 | F37: 4 | G37: =IF(E37="","",IF(E37=B37,"Ja","Nein")) -> Nein | H37: 1000456717 | I37: Kroatien | J37: 4601387450 | K37: 108 | L37: Leaf | M37: Entladen | N37: 0.38888889 | O37: 0.47222222 | P37: 0.49791667 | Q37: 0.51180556 | R37: Yes | V37: =IF(N37="","",IF(O37="","",O37-N37)) -> 0.083333333 | W37: =IF(O37="","",IF(P37="","",P37-O37)) -> 0.025694444 | X37: =IF(P37="","",IF(N37="","",P37-N37)) -> 0.10902778 | Y37: =IF(N37="","",IF(Q37="","",Q37-N37)) -> 0.12291667
A38: =IF(B38="","",WEEKNUM(B38,21)) -> 4 | B38: 45315 | C38: 45315 | D38: =IF(E38="","",WEEKNUM(E38,21)) -> 4 | E38: 45316 | F38: 1 | G38: =IF(E38="","",IF(E38=B38,"Ja","Nein")) -> Nein | H38: 1000453974 | I38: Antwerpen | J38: 126171 | K38: 92 | L38: Leaf | M38: Entladen | N38: 0.3625 | O38: 0.36944444 | P38: 0.39652778 | Q38: 0.40416667 | R38: Yes | V38: =IF(N38="","",IF(O38="","",O38-N38)) -> 0.0069444444 | W38: =IF(O38="","",IF(P38="","",P38-O38)) -> 0.027083333 | X38: =IF(P38="","",IF(N38="","",P38-N38)) -> 0.034027778 | Y38: =IF(N38="","",IF(Q38="","",Q38-N38)) -> 0.041666667
A39: =IF(B39="","",WEEKNUM(B39,21)) -> 4 | B39: 45315 | C39: 45315 | D39: =IF(E39="","",WEEKNUM(E39,21)) -> 4 | E39: 45315 | F39: 2 | G39: =IF(E39="","",IF(E39=B39,"Ja","Nein")) -> Ja | H39: 1000453975 | I39: Antwerpen | J39: 126178 | K39: 96 | L39: Leaf | M39: Entladen | N39: 0.47291667 | O39: 0.49027778 | P39: 0.51666667 | Q39: 0.57291667 | R39: Yes | S39: muss auch verladen werden | V39: =IF(N39="","",IF(O39="","",O39-N39)) -> 0.017361111 | W39: =IF(O39="","",IF(P39="","",P39-O39)) -> 0.026388889 | X39: =IF(P39="","",IF(N39="","",P39-N39)) -> 0.04375 | Y39: =IF(N39="","",IF(Q39="","",Q39-N39)) -> 0.1
A40: =IF(B40="","",WEEKNUM(B40,21)) -> 4 | B40: 45316 | C40: 45316 | D40: =IF(E40="","",WEEKNUM(E40,21)) -> 4 | E40: 45316 | F40: 2 | G40: =IF(E40="","",IF(E40=B40,"Ja","Nein")) -> Ja | H40: 1000454079 | I40: Antwerpen | J40: 126175 | K40: 105 | L40: Leaf | M40: Entladen | N40: 0.55208333 | O40: 0.5625 | P40: 0.58333333 | Q40: 0.66736111 | R40: Yes | S40: docs issue: unkonform gemeldet, falsche Warenummer auf T1 (1030850X); muss auch verladen werden | V40: =IF(N40="","",IF(O40="","",O40-N40)) -> 0.010416667 | W40: =IF(O40="","",IF(P40="","",P40-O40)) -> 0.020833333 | X40: =IF(P40="","",IF(N40="","",P40-N40)) -> 0.03125 | Y40: =IF(N40="","",IF(Q40="","",Q40-N40)) -> 0.11527778
...

Sheet Outbound_Monitor
A1: Auto | B1: Auto | C1: Auto | D1: Ladeplan | E1: Büro | F1: Ladeplan | G1: Büro/Ladeplan | H1: Ladeplan | I1: Ladeplan | J1: Ladeplan | K1: Ladeplan | L1: Ladeplan | M1: Ladeplan | N1: Büro | O1: Büro | P1: Ladeplan | Q1: Ladeplan | R1: Büro | S1: Büro | T1: Büro | U1: Büro | V1: Büro | W1: Büro | X1: Büro | Y1: Büro | Z1: Büro | AA1: Echtzeit Büro | AB1: Echtzeit Büro | AC1: Echtzeit Büro | AD1: Echtzeit Büro | AE1: Echtzeit Lager | AF1: Echtzeit Lager | AG1: Echtzeit Lager | AH1: Büro | AI1: Büro | AJ1: Echtzeit Büro | AK1: Echtzeit Büro | AL1: Echtzeit Büro | AM1: Echtzeit Büro | AN1: Auto | AO1: Auto | AP1: Auto | AQ1: Büro | AR1: Auto | AS1: Büro
A2: KW Plan | B2: KW Update | C2: Timeslot getroffen (Ja / Nein) | D2: PO | E2: Name Navi + kleine Notizen | F2: Plant | G2: Pal/Box | H2: Material Group: Diet CAF Staub Presize Rohware | I2: Source | J2: Destination | K2: Container Type Luftfracht = "AIR" Seefracht = "SEA" | L2: Loading date week | M2: Loading Date Plan DHL | N2: Loading time | O2: SCI | P2: Carrier | Q2: Status | R2: Delivery Note + MISSING STOCK | S2: Abholdatum Update | T2: DN erhalten Datum | U2: DN erhalten Uhrzeit | V2: GI | W2: DHL Express Tracker | X2: Ort Süden/Norden | Y2: Status Verladung | Z2: Verschoben | AA2: Auftrag fertig fürs Lager | AB2: Ankunft Office Datum | AC2: Ankunft Office Uhrzeit | AD2: Ladebeginn | AE2: Ladeende | AF2: Dokumente fertig und dem Fahrer überreicht | AG2: Störungen beim Förderband | AH2: Bemerkungen Büro | AI2: OTM Probleme | AJ2: 1. Ankunft Office Datum | AK2: Ankunft Office Uhrzeit | AL2: 2. Ankunft Office Datum | AM2: Ankunft Office Uhrzeit | AN2: Wartezeit bis Ladebeginn | AO2: Dauer der Verladung | AP2: Dauer von Ankuft bis Ladeende | AQ2: Bemerkungen Lager | AR2: Wochentag lt. Plan | AS2: Ursprüngliches Ladedatum
A3: nn | B3: nn | C3: Ja/Nein | D3: No. | E3: Text | G3: nn | H3: Mat. | I3: City/Country | J3: City/Country | K3: Text | M3: dd.mm.yy | N3: hh:mm | O3: 10000xxxxx | P3: Text | Q3: Text | R3: No. | S3: dd.mm.yy | T3: dd.mm.yy | U3: hh:mm | V3: x | W3: x | X3: Text | Y3: Auswahlliste | Z3: x | AA3: dd:mm:yy | AB3: dd:mm:yy | AC3: hh:mm | AD3: hh:mm | AE3: hh:mm | AF3: hh:mm | AG3: Freitext | AH3: Freitext | AI3: Freitext | AJ3: dd:mm:yy | AK3: hh:mm | AL3: dd:mm:yy | AM3: hh:mm | AN3: hh:mm | AO3: hh:mm | AP3: hh:mm | AQ3: Freitext | AR3: ? | AS3: dd.mm.yy
A4: =IF(M4="","",WEEKNUM(M4,21)) -> 50 | B4: =IF(S4="","",WEEKNUM(S4,21)) -> 1 | D4: 4200211640 | E4: Magda Zusatzaufkleber? Mail "Request to attach warning sign on shipment" | G4: 1 | H4: CAF | J4: Korea 3 | K4: AIR | M4: 45275 | O4: - | P4: DHL Express | R4: 9185059263 | S4: 45294 | V4: x | W4: x | Y4: Verladen | AA4: 45293 | AC4: 0.48680556 | AD4: 0.49027778 | AE4: 0.49166667 | AN4: =IF(AC4="","Kein Eintrag",IF(AD4="","Kein Eintrag",AD4-AC4)) -> 0.0034722222 | AO4: =IF(AF4="","Kein Eintrag",IF(AD4="","Kein Eintrag",AF4-AD4)) -> Kein Eintrag | AP4: =IF(AF4="","Kein Eintrag",IF(AC4="","Kein Eintrag",AF4-AC4)) -> Kein Eintrag
A5: =IF(M5="","",WEEKNUM(M5,21)) -> 51 | B5: =IF(S5="","",WEEKNUM(S5,21)) -> 1 | D5: 4500505491 | E5: Magda Rücksendung 25 KG Lubrin | G5: 1 | H5: Rohware | J5: Givaudan 1 | K5: AIR | M5: 45280 | P5: DHL Express | R5: 9185078064 | S5: 45294 | V5: x | W5: x | Y5: Verladen | AA5: 45293 | AC5: 0.48680556 | AD5: 0.49513889 | AE5: 0.49861111 | AN5: =IF(AC5="","Kein Eintrag",IF(AD5="","Kein Eintrag",AD5-AC5)) -> 0.0083333333 | AO5: =IF(AF5="","Kein Eintrag",IF(AD5="","Kein Eintrag",AF5-AD5)) -> Kein Eintrag | AP5: =IF(AF5="","Kein Eintrag",IF(AC5="","Kein Eintrag",AF5-AC5)) -> Kein Eintrag
A6: =IF(M6="","",WEEKNUM(M6,21)) -> 1 | B6: =IF(S6="","",WEEKNUM(S6,21)) -> 1 | D6: 4702146147 | E6: Inga | G6: 1 | H6: CAF | J6: Kanfanar 1 | K6: AIR | M6: 45294 | O6: - | P6: DHL Express | R6: 9184943892 | S6: 45294 | V6: x | W6: x | Y6: Verladen | AA6: 45293 | AC6: 0.48680556 | AD6: 0.49236111 | AE6: 0.49444444
A7: =IF(M7="","",WEEKNUM(M7,21)) -> 1 | B7: =IF(S7="","",WEEKNUM(S7,21)) -> 1 | D7: 4100038296 | E7: Magda Preise passen jetzt - kann navigiert werden, E-Mail by Annie am 03.01. um 13:15 Uhr | F7: TR45 | G7: 102 | H7: Diet | I7: Bayreuth | J7: Gebze 1 | K7: Box Trailer | L7: 1 | M7: 45295 | O7: 1000448075 | P7: GOPET | Q7: CONFIRMED | R7: 9185038111 | S7: 45295 | V7: x | X7: süden | Y7: Verladen | AA7: 45294 | AB7: 45295 | AC7: 0.39236111 | AD7: 0.45833333 | AE7: 0.5 | AF7: 0.59722222 | AN7: =IF(AC7="","Kein Eintrag",IF(AD7="","Kein Eintrag",AD7-AC7)) -> 0.065972222 | AO7: =IF(AF7="","Kein Eintrag",IF(AD7="","Kein Eintrag",AF7-AD7)) -> 0.13888889 | AP7: =IF(AF7="","Kein Eintrag",IF(AC7="","Kein Eintrag",AF7-AC7)) -> 0.20486111
A8: =IF(M8="","",WEEKNUM(M8,21)) -> 1 | B8: =IF(S8="","",WEEKNUM(S8,21)) -> 1 | D8: 4100038301 | E8: Magda Preise passen jetzt - kann navigiert werden, E-Mail by Annie am 03.01. um 13:15 Uhr | F8: TR45 | G8: 102 | H8: Diet | I8: Bayreuth | J8: Gebze 2 | K8: Box Trailer | L8: 1 | M8: 45295 | O8: 1000448076 | P8: ASSTRA | Q8: CONFIRMED | R8: 9185088748 | S8: 45295 | V8: x | X8: Süden | Y8: Verladen | AA8: 45294 | AB8: 45295 | AC8: 0.28125 | AD8: 0.30208333 | AE8: 0.38888889 | AF8: 0.45833333 | AN8: =IF(AC8="","Kein Eintrag",IF(AD8="","Kein Eintrag",AD8-AC8)) -> 0.020833333 | AO8: =IF(AF8="","Kein Eintrag",IF(AD8="","Kein Eintrag",AF8-AD8)) -> 0.15625 | AP8: =IF(AF8="","Kein Eintrag",IF(AC8="","Kein Eintrag",AF8-AC8)) -> 0.17708333
A9: =IF(M9="","",WEEKNUM(M9,21)) -> 1 | B9: =IF(S9="","",WEEKNUM(S9,21)) -> 1 | D9: 4702083669 | E9: Alexander | F9: PL37 | G9: 102 | H9: Diet | I9: Bayreuth | J9: Poznan 1 | K9: Box Trailer | L9: 1 | M9: 45295 | O9: 1000448278 | P9: EUROGATE | Q9: CONFIRMED | R9: 9185035992 | S9: 45295 | V9: x | X9: süden | Y9: Verladen | AA9: 45293 | AB9: 45295 | AC9: 0.46875 | AD9: 0.52083333 | AE9: 0.55902778 | AF9: 0.6 | AN9: =IF(AC9="","Kein Eintrag",IF(AD9="","Kein Eintrag",AD9-AC9)) -> 0.052083333 | AO9: =IF(AF9="","Kein Eintrag",IF(AD9="","Kein Eintrag",AF9-AD9)) -> 0.079166667 | AP9: =IF(AF9="","Kein Eintrag",IF(AC9="","Kein Eintrag",AF9-AC9)) -> 0.13125
A10: =IF(M10="","",WEEKNUM(M10,21)) -> 1 | B10: =IF(S10="","",WEEKNUM(S10,21)) -> 1 | D10: 4702083687 | E10: Alexander | F10: PL37 | G10: 102 | H10: Diet | I10: Bayreuth | J10: Poznan 2 | K10: Box Trailer | L10: 1 | M10: 45295 | O10: 1000448279 | P10: EUROGATE | Q10: CONFIRMED | R10: 9185035993 | S10: 45295 | V10: x | X10: Süden | Y10: Verladen | AA10: 45293 | AB10: 45295 | AC10: 0.38541667 | AD10: 0.40625 | AE10: 0.4375 | AF10: 0.47638889 | AN10: =IF(AC10="","Kein Eintrag",IF(AD10="","Kein Eintrag",AD10-AC10)) -> 0.020833333 | AO10: =IF(AF10="","Kein Eintrag",IF(AD10="","Kein Eintrag",AF10-AD10)) -> 0.070138889 | AP10: =IF(AF10="","Kein Eintrag",IF(AC10="","Kein Eintrag",AF10-AC10)) -> 0.090972222
A11: =IF(M11="","",WEEKNUM(M11,21)) -> 1 | B11: =IF(S11="","",WEEKNUM(S11,21)) -> 1 | D11: 4702108619 | E11: Alexander | F11: HU12 | G11: 102 | H11: Diet | I11: Bayreuth | J11: Pecs 1 | K11: Box Trailer | L11: 1 | M11: 45295 | O11: 1000448867 | P11: LOG-IN | Q11: CONFIRMED | R11: 9185057402 | S11: 45295 | V11: x | X11: süden | Y11: Verladen | AA11: 45293 | AB11: 45295 | AC11: 0.52083333 | AD11: 0.57291667 | AE11: 0.59375 | AF11: 0.64166667 | AN11: =IF(AC11="","Kein Eintrag",IF(AD11="","Kein Eintrag",AD11-AC11)) -> 0.052083333 | AO11: =IF(AF11="","Kein Eintrag",IF(AD11="","Kein Eintrag",AF11-AD11)) -> 0.06875 | AP11: =IF(AF11="","Kein Eintrag",IF(AC11="","Kein Eintrag",AF11-AC11)) -> 0.12083333
A12: =IF(M12="","",WEEKNUM(M12,21)) -> 1 | B12: =IF(S12="","",WEEKNUM(S12,21)) -> 1 | D12: 4100038303 | E12: Magda | F12: TR45 | G12: 102 | H12: Diet | I12: Bayreuth | J12: Gebze 4 | K12: Box Trailer | L12: 1 | M12: 45296 | O12: 1000448271 | P12: DHL TURKEY | Q12: CONFIRMED | R12: 9185033172 | S12: 45295 | X12: süden | Y12: Verladen | AA12: 45295 | AB12: 45295 | AC12: 0.39583333 | AD12: 0.60416667 | AF12: 0.72777778 | AN12: =IF(AC12="","Kein Eintrag",IF(AD12="","Kein Eintrag",AD12-AC12)) -> 0.20833333 | AO12: =IF(AF12="","Kein Eintrag",IF(AD12="","Kein Eintrag",AF12-AD12)) -> 0.12361111 | AP12: =IF(AF12="","Kein Eintrag",IF(AC12="","Kein Eintrag",AF12-AC12)) -> 0.33194444
A13: =IF(M13="","",WEEKNUM(M13,21)) -> 1 | B13: =IF(S13="","",WEEKNUM(S13,21)) -> 1 | D13: 4200209553 | E13: Inga / Preise für 2024 sind ok | G13: 2 | H13: CAF | J13: Jordan 1 | K13: 20 FT | M13: 45294 | N13: 0.375 | O13: 1000448716 | P13: MSC | R13: 9184945836 | S13: 45295 | V13: x | X13: Süden | Y13: Verladen | AA13: 45293 | AB13: 45295 | AC13: 0.35763889 | AD13: 0.38194444 | AE13: 0.40625 | AN13: =IF(AC13="","Kein Eintrag",IF(AD13="","Kein Eintrag",AD13-AC13)) -> 0.024305556 | AO13: =IF(AF13="","Kein Eintrag",IF(AD13="","Kein Eintrag",AF13-AD13)) -> Kein Eintrag | AP13: =IF(AF13="","Kein Eintrag",IF(AC13="","Kein Eintrag",AF13-AC13)) -> Kein Eintrag
A14: =IF(M14="","",WEEKNUM(M14,21)) -> 1 | B14: =IF(S14="","",WEEKNUM(S14,21)) -> 1 | D14: 4100038302 | E14: Magda | F14: TR45 | G14: 102 | H14: Diet | I14: Bayreuth | J14: Gebze 3 | K14: Box Trailer | L14: 1 | M14: 45296 | O14: 1000448270 | P14: ASSTRA | Q14: CONFIRMED | R14: 9185085514 | S14: 45296 | V14: x | X14: Süden | Y14: Verladen | AA14: 45295 | AB14: 45296 | AC14: 0.26736111 | AD14: 0.29166667 | AE14: 0.35763889 | AF14: 0.44791667 | AN14: =IF(AC14="","Kein Eintrag",IF(AD14="","Kein Eintrag",AD14-AC14)) -> 0.024305556 | AO14: =IF(AF14="","Kein Eintrag",IF(AD14="","Kein Eintrag",AF14-AD14)) -> 0.15625 | AP14: =IF(AF14="","Kein Eintrag",IF(AC14="","Kein Eintrag",AF14-AC14)) -> 0.18055556
A15: =IF(M15="","",WEEKNUM(M15,21)) -> 1 | B15: =IF(S15="","",WEEKNUM(S15,21)) -> 1 | D15: 4702081695 | E15: Brauni, Fahrer hatte später seine Dokumente kommen, aufgrund eines Fehlers in SAP /isuse with GI posting on 05.01.2024 at 09:30 h | F15: HU12 | G15: 102 | H15: Diet | I15: Bayreuth | J15: Pecs 3 | K15: Box Trailer | L15: 1 | M15: 45296 | O15: 1000448868 | P15: LOG-IN | Q15: CONFIRMED | R15: 9184971913 | S15: 45296 | V15: x | X15: Süden | Y15: Verladen | AA15: 45294 | AB15: 45296 | AC15: 0.34027778 | AD15: 0.375 | AE15: 0.42708333 | AF15: 0.57291667 | AN15: =IF(AC15="","Kein Eintrag",IF(AD15="","Kein Eintrag",AD15-AC15)) -> 0.034722222 | AO15: =IF(AF15="","Kein Eintrag",IF(AD15="","Kein Eintrag",AF15-AD15)) -> 0.19791667 | AP15: =IF(AF15="","Kein Eintrag",IF(AC15="","Kein Eintrag",AF15-AC15)) -> 0.23263889
A16: =IF(M16="","",WEEKNUM(M16,21)) -> 1 | B16: =IF(S16="","",WEEKNUM(S16,21)) -> 1 | D16: 4702113220 | E16: Brauni | F16: RO33 | G16: 102 | H16: Diet | I16: Bayreuth | J16: Ploiesti 2 | K16: Box Trailer | L16: 1 | M16: 45296 | O16: 1000448277 | P16: AQUILA | Q16: CONFIRMED | R16: 9185067814 | S16: 45296 | V16: x | X16: Süden | Y16: Verladen | AA16: 45294 | AB16: 45296 | AC16: 0.38541667 | AD16: 0.4375 | AE16: 0.47222222 | AF16: 0.59375 | AN16: =IF(AC16="","Kein Eintrag",IF(AD16="","Kein Eintrag",AD16-AC16)) -> 0.052083333 | AO16: =IF(AF16="","Kein Eintrag",IF(AD16="","Kein Eintrag",AF16-AD16)) -> 0.15625 | AP16: =IF(AF16="","Kein Eintrag",IF(AC16="","Kein Eintrag",AF16-AC16)) -> 0.20833333
A17: =IF(M17="","",WEEKNUM(M17,21)) -> 1 | B17: =IF(S17="","",WEEKNUM(S17,21)) -> 1 | D17: 4702144181 | E17: Brauni | F17: PL37 | G17: 102 | H17: Diet | I17: Bayreuth | J17: Poznan 3 | K17: Box Trailer | L17: 1 | M17: 45296 | O17: 1000448280 | P17: EUROGATE | Q17: CONFIRMED | R17: 9185077314 | S17: 45296 | V17: x | X17: Süden | Y17: Verladen | AA17: 45294 | AB17: 45296 | AC17: 0.51041667 | AD17: 0.54166667 | AE17: 0.59375 | AF17: 0.64236111 | AN17: =IF(AC17="","Kein Eintrag",IF(AD17="","Kein Eintrag",AD17-AC17)) -> 0.03125 | AO17: =IF(AF17="","Kein Eintrag",IF(AD17="","Kein Eintrag",AF17-AD17)) -> 0.10069444 | AP17: =IF(AF17="","Kein Eintrag",IF(AC17="","Kein Eintrag",AF17-AC17)) -> 0.13194444
A18: =IF(M18="","",WEEKNUM(M18,21)) -> 1 | B18: =IF(S18="","",WEEKNUM(S18,21)) -> 1 | D18: 4702144183 | E18: Brauni | F18: PL37 | G18: 102 | H18: Diet | I18: Bayreuth | J18: Poznan 4 | K18: Box Trailer | L18: 1 | M18: 45296 | O18: 1000448281 | P18: EUROGATE | Q18: CONFIRMED | R18: 9185076411 | S18: 45296 | V18: x | X18: Süden | Y18: Verladen | AA18: 45294 | AB18: 45296 | AC18: 0.52777778 | AD18: 0.60416667 | AE18: 0.675 | AF18: 0.69097222 | AN18: =IF(AC18="","Kein Eintrag",IF(AD18="","Kein Eintrag",AD18-AC18)) -> 0.076388889 | AO18: =IF(AF18="","Kein Eintrag",IF(AD18="","Kein Eintrag",AF18-AD18)) -> 0.086805556 | AP18: =IF(AF18="","Kein Eintrag",IF(AC18="","Kein Eintrag",AF18-AC18)) -> 0.16319444
A19: =IF(M19="","",WEEKNUM(M19,21)) -> 1 | B19: =IF(S19="","",WEEKNUM(S19,21)) -> 2 | D19: 4702081694 | E19: Alexander | F19: HU12 | G19: 102 | H19: Diet | I19: Bayreuth | J19: Pecs 2 | K19: Box Trailer | L19: 1 | M19: 45296 | O19: 1000448870 | P19: LOG-IN | Q19: CONFIRMED | R19: 9185080997 | S19: 45299 | V19: x | X19: Süden | Y19: Verladen | AA19: 45293 | AB19: 45299 | AC19: 0.27777778 | AD19: 0.29166667 | AE19: 0.32291667 | AN19: =IF(AC19="","Kein Eintrag",IF(AD19="","Kein Eintrag",AD19-AC19)) -> 0.013888889 | AO19: =IF(AF19="","Kein Eintrag",IF(AD19="","Kein Eintrag",AF19-AD19)) -> Kein Eintrag | AP19: =IF(AF19="","Kein Eintrag",IF(AC19="","Kein Eintrag",AF19-AC19)) -> Kein Eintrag
A20: =IF(M20="","",WEEKNUM(M20,21)) -> 1 | B20: =IF(S20="","",WEEKNUM(S20,21)) -> 2 | D20: 4702108629 | E20: Brauni, kurze Fahr- und Schichtzeit hatte der LKW Fahrer am Freitag, 05.01.2024 | F20: HU12 | G20: 102 | H20: Diet | I20: Bayreuth | J20: Pecs 4 | K20: Box Trailer | L20: 1 | M20: 45296 | O20: 1000448869 | P20: LOG-IN | Q20: CONFIRMED | R20: 9185076410 | S20: 45299 | V20: x | X20: Süden | Y20: Verladen | AA20: 45294 | AB20: 45299 | AC20: 0.27777778 | AD20: 0.33333333 | AE20: 0.40625 | AJ20: 45296 | AK20: 0.54166667 | AN20: =IF(AC20="","Kein Eintrag",IF(AD20="","Kein Eintrag",AD20-AC20)) -> 0.055555556 | AO20: =IF(AF20="","Kein Eintrag",IF(AD20="","Kein Eintrag",AF20-AD20)) -> Kein Eintrag | AP20: =IF(AF20="","Kein Eintrag",IF(AC20="","Kein Eintrag",AF20-AC20)) -> Kein Eintrag
A21: =IF(M21="","",WEEKNUM(M21,21)) -> 2 | B21: =IF(S21="","",WEEKNUM(S21,21)) -> 2 | D21: 4702116766 | E21: Magda | G21: 68 | H21: Presize | J21: Ploiesti 12 | K21: Box Trailer | M21: 45299 | O21: 1000449066 | P21: SC VIOTRANS | R21: 9185092435 | S21: 45299 | V21: x | X21: Süden | Y21: Verladen | AA21: 45295 | AB21: 45299 | AC21: 0.29861111 | AD21: 0.375 | AE21: 0.41666667 | AN21: =IF(AC21="","Kein Eintrag",IF(AD21="","Kein Eintrag",AD21-AC21)) -> 0.076388889 | AO21: =IF(AF21="","Kein Eintrag",IF(AD21="","Kein Eintrag",AF21-AD21)) -> Kein Eintrag | AP21: =IF(AF21="","Kein Eintrag",IF(AC21="","Kein Eintrag",AF21-AC21)) -> Kein Eintrag
A22: =IF(M22="","",WEEKNUM(M22,21)) -> 2 | B22: =IF(S22="","",WEEKNUM(S22,21)) -> 2 | D22: 4702143217 | E22: Magda Siehe E-Mail STO TRACKER 4702143217 BAY>PECS 1 pallet 120 KG | G22: 1 | H22: Rohware | J22: Pecs 5 | K22: Thermo VAN | M22: 45299 | O22: 1000449195 | P22: UNIFLEX HUNGARY | R22: 9184850379 | S22: 45299 | V22: x | X22: Süden | Y22: Verladen | AA22: 45295 | AB22: 45299 | AC22: 0.61111111 | AD22: 0.625 | AE22: 0.62847222 | AH22: KT 19.12: Siehe E-Mail - bzgl. Personalmangel auf Januar verschoben | AN22: =IF(AC22="","Kein Eintrag",IF(AD22="","Kein Eintrag",AD22-AC22)) -> 0.013888889 | AO22: =IF(AF22="","Kein Eintrag",IF(AD22="","Kein Eintrag",AF22-AD22)) -> Kein Eintrag | AP22: =IF(AF22="","Kein Eintrag",IF(AC22="","Kein Eintrag",AF22-AC22)) -> Kein Eintrag
A23: =IF(M23="","",WEEKNUM(M23,21)) -> 2 | B23: =IF(S23="","",WEEKNUM(S23,21)) -> 2 | D23: 4702120119 | E23: Magda | G23: 1 | H23: CAF | J23: Kanfanar 31 | M23: 45299 | O23: 1000449382 | P23: Trans East | R23: 9185103876 | S23: 45299 | T23: 45299 | X23: Süden | Y23: Verladen | AA23: 45299 | AB23: 45299 | AC23: 0.48611111 | AD23: 0.51388889 | AE23: 0.52083333 | AF23: 0.52430556 | AN23: =IF(AC23="","Kein Eintrag",IF(AD23="","Kein Eintrag",AD23-AC23)) -> 0.027777778 | AO23: =IF(AF23="","Kein Eintrag",IF(AD23="","Kein Eintrag",AF23-AD23)) -> 0.010416667 | AP23: =IF(AF23="","Kein Eintrag",IF(AC23="","Kein Eintrag",AF23-AC23)) -> 0.038194444
A24: =IF(M24="","",WEEKNUM(M24,21)) -> 2 | B24: =IF(S24="","",WEEKNUM(S24,21)) -> 2 | D24: 4702081653 | E24: Brauni, LKW ist am 08-01-2024 nicht gekommen | F24: HR12 | G24: 102 | H24: Diet | I24: Bayreuth | J24: Kanfanar 1 | K24: Box Trailer | L24: 2 | M24: 45299 | N24: 45597 | O24: 1000449524 | P24: TRANSEAST | Q24: CONFIRMED | R24: 9185019274 | S24: 45300 | V24: x | X24: Süden | Y24: Verladen | AA24: 45299 | AB24: 45300 | AC24: 0.31597222 | AD24: 0.35555556 | AE24: 0.39722222 | AF24: 0.41875 | AN24: =IF(AC24="","Kein Eintrag",IF(AD24="","Kein Eintrag",AD24-AC24)) -> 0.039583333 | AO24: =IF(AF24="","Kein Eintrag",IF(AD24="","Kein Eintrag",AF24-AD24)) -> 0.063194444 | AP24: =IF(AF24="","Kein Eintrag",IF(AC24="","Kein Eintrag",AF24-AC24)) -> 0.10277778
A25: =IF(M25="","",WEEKNUM(M25,21)) -> 2 | B25: =IF(S25="","",WEEKNUM(S25,21)) -> 2 | D25: 4702081673 | E25: Inga | F25: HU12 | G25: 102 | H25: Diet | I25: Bayreuth | J25: Pecs 1 | K25: Box Trailer | L25: 2 | M25: 45300 | N25: 45597 | O25: 1000450126 | P25: LOG-IN | Q25: REQUESTED | R25: 9185129976 | S25: 45300 | V25: x | X25: süden | Y25: Verladen | AA25: 45299 | AB25: 45300 | AC25: 0.42708333 | AD25: 0.5 | AE25: 0.53472222 | AF25: 0.55416667 | AN25: =IF(AC25="","Kein Eintrag",IF(AD25="","Kein Eintrag",AD25-AC25)) -> 0.072916667 | AO25: =IF(AF25="","Kein Eintrag",IF(AD25="","Kein Eintrag",AF25-AD25)) -> 0.054166667 | AP25: =IF(AF25="","Kein Eintrag",IF(AC25="","Kein Eintrag",AF25-AC25)) -> 0.12708333
A26: =IF(M26="","",WEEKNUM(M26,21)) -> 2 | B26: =IF(S26="","",WEEKNUM(S26,21)) -> 2 | D26: 4702081675 | E26: Inga | F26: HU12 | G26: 102 | H26: Diet | I26: Bayreuth | J26: Pecs 2 | K26: Box Trailer | L26: 2 | M26: 45300 | N26: 45597 | O26: 1000449526 | P26: ESSERS | Q26: CONFIRMED | R26: 9185132517 | S26: 45300 | V26: x | X26: Süden | Y26: Verladen | AA26: 45299 | AB26: 45300 | AC26: 0.3125 | AD26: 0.33333333 | AE26: 0.36111111 | AF26: 0.38333333 | AN26: =IF(AC26="","Kein Eintrag",IF(AD26="","Kein Eintrag",AD26-AC26)) -> 0.020833333 | AO26: =IF(AF26="","Kein Eintrag",IF(AD26="","Kein Eintrag",AF26-AD26)) -> 0.05 | AP26: =IF(AF26="","Kein Eintrag",IF(AC26="","Kein Eintrag",AF26-AC26)) -> 0.070833333
A27: =IF(M27="","",WEEKNUM(M27,21)) -> 2 | B27: =IF(S27="","",WEEKNUM(S27,21)) -> 2 | D27: 4702112510 | E27: Inga | F27: RO33 | G27: 102 | H27: Diet | I27: Bayreuth | J27: Ploiesti 1 | K27: Box Trailer | L27: 2 | M27: 45300 | N27: 45627 | O27: 1000449527 | P27: AQUILA | Q27: CONFIRMED | R27: 9185101942 | S27: 45300 | V27: x | X27: Süden | Y27: Verladen | AA27: 45299 | AB27: 45300 | AC27: 0.32638889 | AD27: 0.41666667 | AE27: 0.46527778 | AF27: 0.49236111 | AN27: =IF(AC27="","Kein Eintrag",IF(AD27="","Kein Eintrag",AD27-AC27)) -> 0.090277778 | AO27: =IF(AF27="","Kein Eintrag",IF(AD27="","Kein Eintrag",AF27-AD27)) -> 0.075694444 | AP27: =IF(AF27="","Kein Eintrag",IF(AC27="","Kein Eintrag",AF27-AC27)) -> 0.16597222
A28: =IF(M28="","",WEEKNUM(M28,21)) -> 2 | B28: =IF(S28="","",WEEKNUM(S28,21)) -> 2 | D28: 4702120083 | E28: Magda war nicht gemeldet v. DHL am 08.01.2024 | F28: CAF | G28: 23 | H28: CAF | I28: Bayreuth | J28: Augustow 1 | K28: Thermo Truck | L28: Yes | M28: 45299 | O28: 1000449375 | P28: EUROGATE | Q28: 1000449375 | R28: 9185093949 | S28: 45300 | V28: x | X28: Süden | Y28: Verladen | AA28: 44934 | AB28: 45300 | AC28: 0.51388889 | AD28: 0.53125 | AE28: 0.55208333 | AF28: 0.57291667 | AN28: =IF(AC28="","Kein Eintrag",IF(AD28="","Kein Eintrag",AD28-AC28)) -> 0.017361111 | AO28: =IF(AF28="","Kein Eintrag",IF(AD28="","Kein Eintrag",AF28-AD28)) -> 0.041666667 | AP28: =IF(AF28="","Kein Eintrag",IF(AC28="","Kein Eintrag",AF28-AC28)) -> 0.059027778
A29: =IF(M29="","",WEEKNUM(M29,21)) -> 2 | B29: =IF(S29="","",WEEKNUM(S29,21)) -> 2 | D29: 4702116572 | E29: Magda war nicht gemeldet v. DHL am 08.01.2024 | G29: 37 | H29: CAF | J29: Ploiesti 35 | K29: Thermo Truck | M29: 45299 | O29: 1000449992 | P29: SC VIOTRANS | R29: 9185128540 | S29: 45300 | V29: x | X29: Süden | Y29: Verladen | AA29: 45299 | AB29: 45300 | AC29: 0.35763889 | AD29: 0.36805556 | AE29: 0.39583333 | AF29: 0.43055556 | AJ29: 45299 | AK29: 0.375 | AN29: =IF(AC29="","Kein Eintrag",IF(AD29="","Kein Eintrag",AD29-AC29)) -> 0.010416667 | AO29: =IF(AF29="","Kein Eintrag",IF(AD29="","Kein Eintrag",AF29-AD29)) -> 0.0625 | AP29: =IF(AF29="","Kein Eintrag",IF(AC29="","Kein Eintrag",AF29-AC29)) -> 0.072916667
A30: =IF(M30="","",WEEKNUM(M30,21)) -> 2 | B30: =IF(S30="","",WEEKNUM(S30,21)) -> 2 | D30: 4200208883 | E30: Inga war nicht gemeldet v. DHL am 08.01.2024 | F30: CAF | G30: 7 | H30: CAF | I30: Bayreuth | J30: Landskrona 1 | K30: Thermo Van | L30: Yes | M30: 45300 | O30: 1000449861 | P30: ASSTRA | Q30: 1000449861 | R30: 9185121530 | S30: 45300 | V30: x | X30: Süden | Y30: Verladen | AA30: 45300 | AB30: 45300 | AC30: 0.41666667 | AD30: 0.47569444 | AE30: 0.48263889 | AF30: 0.48958333 | AN30: =IF(AC30="","Kein Eintrag",IF(AD30="","Kein Eintrag",AD30-AC30)) -> 0.059027778 | AO30: =IF(AF30="","Kein Eintrag",IF(AD30="","Kein Eintrag",AF30-AD30)) -> 0.013888889 | AP30: =IF(AF30="","Kein Eintrag",IF(AC30="","Kein Eintrag",AF30-AC30)) -> 0.072916667
A31: =IF(M31="","",WEEKNUM(M31,21)) -> 2 | B31: =IF(S31="","",WEEKNUM(S31,21)) -> 2 | D31: 4200211128 | E31: Magda, LKW ist am 08-01-2024 nicht gekommen | F31: RS04 | G31: 102 | H31: Diet | I31: Bayreuth | J31: Vranje 1 | K31: Box Trailer | L31: 2 | M31: 45299 | N31: 45597 | O31: 1000449530 | P31: FERCAM | Q31: CONFIRMED | R31: 9185108040 | S31: 45301 | V31: x | X31: Süden | Y31: Verladen | AA31: 45296 | AB31: 45301 | AC31: 0.37847222 | AD31: 0.39583333 | AE31: 0.47222222 | AF31: 0.5625 | AN31: =IF(AC31="","Kein Eintrag",IF(AD31="","Kein Eintrag",AD31-AC31)) -> 0.017361111 | AO31: =IF(AF31="","Kein Eintrag",IF(AD31="","Kein Eintrag",AF31-AD31)) -> 0.16666667 | AP31: =IF(AF31="","Kein Eintrag",IF(AC31="","Kein Eintrag",AF31-AC31)) -> 0.18402778
A32: =IF(M32="","",WEEKNUM(M32,21)) -> 2 | B32: =IF(S32="","",WEEKNUM(S32,21)) -> 2 | D32: 4702081765 | E32: muss LEAF abladen Magda, LKW ist am 08-01-2024 nicht gekommen | F32: PL37 | G32: 102 | H32: Diet | I32: Bayreuth | J32: Poznan 1 | K32: Box Trailer | L32: 2 | M32: 45299 | N32: 45536 | O32: 1000449528 | P32: EUROGATE | Q32: CONFIRMED | R32: 9185078963 | S32: 45301 | V32: x | X32: Süden | Y32: Verladen | AA32: 45296 | AB32: 45301 | AC32: 0.38888889 | AD32: 0.52083333 | AE32: 0.55208333 | AF32: 0.58333333 | AN32: =IF(AC32="","Kein Eintrag",IF(AD32="","Kein Eintrag",AD32-AC32)) -> 0.13194444 | AO32: =IF(AF32="","Kein Eintrag",IF(AD32="","Kein Eintrag",AF32-AD32)) -> 0.0625 | AP32: =IF(AF32="","Kein Eintrag",IF(AC32="","Kein Eintrag",AF32-AC32)) -> 0.19444444
A33: =IF(M33="","",WEEKNUM(M33,21)) -> 2 | B33: =IF(S33="","",WEEKNUM(S33,21)) -> 2 | D33: 4702081654 | E33: Inga | F33: HR12 | G33: 102 | H33: Diet | I33: Bayreuth | J33: Kanfanar 2 | K33: Box Trailer | L33: 2 | M33: 45300 | N33: 45597 | O33: 1000449525 | P33: TRANSEAST | Q33: CONFIRMED | R33: 9185132516 | S33: 45301 | V33: x | X33: Süden | Y33: Verladen | AA33: 45299 | AB33: 45301 | AC33: 0.61458333 | AE33: 0.65277778 | AF33: 0.6875 | AN33: =IF(AC33="","Kein Eintrag",IF(AD33="","Kein Eintrag",AD33-AC33)) -> Kein Eintrag | AO33: =IF(AF33="","Kein Eintrag",IF(AD33="","Kein Eintrag",AF33-AD33)) -> Kein Eintrag | AP33: =IF(AF33="","Kein Eintrag",IF(AC33="","Kein Eintrag",AF33-AC33)) -> 0.072916667
A34: =IF(M34="","",WEEKNUM(M34,21)) -> 2 | B34: =IF(S34="","",WEEKNUM(S34,21)) -> 2 | D34: 4702083631 | E34: Inga | F34: PL37 | G34: 102 | H34: Diet | I34: Bayreuth | J34: Poznan 3 | K34: Box Trailer | L34: 2 | M34: 45300 | N34: 45566 | O34: 1000449529 | P34: EUROGATE | Q34: CONFIRMED | R34: 9185114494 | S34: 45301 | V34: x | X34: Süden | Y34: Verladen | AA34: 45299 | AB34: 45301 | AC34: 0.43055556 | AD34: 0.47916667 | AE34: 0.51041667 | AF34: 0.54166667 | AN34: =IF(AC34="","Kein Eintrag",IF(AD34="","Kein Eintrag",AD34-AC34)) -> 0.048611111 | AO34: =IF(AF34="","Kein Eintrag",IF(AD34="","Kein Eintrag",AF34-AD34)) -> 0.0625 | AP34: =IF(AF34="","Kein Eintrag",IF(AC34="","Kein Eintrag",AF34-AC34)) -> 0.11111111
A35: =IF(M35="","",WEEKNUM(M35,21)) -> 2 | B35: =IF(S35="","",WEEKNUM(S35,21)) -> 2 | D35: 4702116749 | E35: muss LEAF abladen Inga | G35: 68 | H35: Presize | J35: Poznan 20 | K35: Box Trailer | M35: 45300 | O35: 1000449462 | R35: 9185111010 | S35: 45301 | V35: x | X35: Süden | Y35: Verladen | AA35: 45299 | AB35: 45301 | AC35: 0.37152778 | AD35: 0.40972222 | AE35: 0.42708333 | AN35: =IF(AC35="","Kein Eintrag",IF(AD35="","Kein Eintrag",AD35-AC35)) -> 0.038194444 | AO35: =IF(AF35="","Kein Eintrag",IF(AD35="","Kein Eintrag",AF35-AD35)) -> Kein Eintrag | AP35: =IF(AF35="","Kein Eintrag",IF(AC35="","Kein Eintrag",AF35-AC35)) -> Kein Eintrag
A36: =IF(M36="","",WEEKNUM(M36,21)) -> 2 | B36: =IF(S36="","",WEEKNUM(S36,21)) -> 2 | D36: 4702083689 | E36: Magda | F36: PL37 | G36: 102 | H36: Diet | I36: Bayreuth | J36: Poznan 6 | K36: Box Trailer | L36: 2 | M36: 45302 | O36: 1000450125 | P36: FT LOGISTICS | Q36: CONFIRMED | R36: 9185114283 | S36: 45302 | V36: x | X36: Süden | Y36: Verladen | AA36: 45300 | AB36: 45302 | AC36: 0.56597222 | AD36: 0.58333333 | AE36: 0.60763889 | AF36: 0.64791667 | AN36: =IF(AC36="","Kein Eintrag",IF(AD36="","Kein Eintrag",AD36-AC36)) -> 0.017361111 | AO36: =IF(AF36="","Kein Eintrag",IF(AD36="","Kein Eintrag",AF36-AD36)) -> 0.064583333 | AP36: =IF(AF36="","Kein Eintrag",IF(AC36="","Kein Eintrag",AF36-AC36)) -> 0.081944444
A37: =IF(M37="","",WEEKNUM(M37,21)) -> 2 | B37: =IF(S37="","",WEEKNUM(S37,21)) -> 2 | D37: 4702146931 | E37: Magda / PRIO Soll am 10.01. abgeholt werden, Preis fehlt!!!!! E-Mail Am 10.01.2023 um 13:10 Uhr | F37: CH16 | G37: 18 | H37: Diet | I37: Bayreuth | J37: Boncourt 2 | K37: Box Trailer | L37: 2 | M37: 45302 | N37: PRIO | O37: 1000451078 | P37: LOG-IN | R37: 9185191090 | S37: 45302 | V37: x | X37: Süden | Y37: Verladen | AA37: 45301 | AB37: 45302 | AC37: 0.33333333 | AD37: 0.35416667 | AE37: 0.375 | AF37: 10:;15 | AN37: =IF(AC37="","Kein Eintrag",IF(AD37="","Kein Eintrag",AD37-AC37)) -> 0.020833333 | AO37: =IF(AF37="","Kein Eintrag",IF(AD37="","Kein Eintrag",AF37-AD37)) -> #VALUE! | AP37: =IF(AF37="","Kein Eintrag",IF(AC37="","Kein Eintrag",AF37-AC37)) -> #VALUE!
A38: =IF(M38="","",WEEKNUM(M38,21)) -> 2 | B38: =IF(S38="","",WEEKNUM(S38,21)) -> 2 | D38: 4200209665 | E38: Inga Driver: Roman Moravek Truck Plate: TIR-ZL-144 Chassi-Plate: HO-CT-3027 Cont. TXGU5524673 | G38: 19 | H38: CAF | J38: Samsun 1 | K38: SEA | M38: 45302 | N38: 0.41666667 | O38: 1000449952 | R38: 9185014113 | S38: 45302 | V38: x | X38: Süden | Y38: Verladen | AA38: 45300 | AB38: 45302 | AC38: 0.40277778 | AD38: 0.41666667 | AE38: 0.44791667 | AF38: 0.52083333 | AN38: =IF(AC38="","Kein Eintrag",IF(AD38="","Kein Eintrag",AD38-AC38)) -> 0.013888889 | AO38: =IF(AF38="","Kein Eintrag",IF(AD38="","Kein Eintrag",AF38-AD38)) -> 0.10416667 | AP38: =IF(AF38="","Kein Eintrag",IF(AC38="","Kein Eintrag",AF38-AC38)) -> 0.11805556 | AS38: 45302
A39: =IF(M39="","",WEEKNUM(M39,21)) -> 2 | B39: =IF(S39="","",WEEKNUM(S39,21)) -> 2 | D39: 4702154353 | E39: Inga | G39: 1 | H39: BBK | J39: Boncourt 2 | K39: Thermo Van | M39: 45302 | O39: 1000451155 | R39: 9185158487 | S39: 45302 | V39: x | X39: Süden | Y39: Verladen | AA39: 45302 | AB39: 45302 | AC39: 0.53819444 | AD39: 0.56944444 | AE39: 0.57291667 | AF39: 0.72916667
A40: =IF(M40="","",WEEKNUM(M40,21)) -> 2 | B40: =IF(S40="","",WEEKNUM(S40,21)) -> 2 | D40: 4702145226 | E40: ADR vorhanden Inga /ADR! Über 1000 Punkte! | F40: CAF | G40: 4 | H40: CAF | I40: Bayreuth | J40: Boncourt 1 | K40: Thermo Van | L40: Yes | M40: 45302 | O40: 1000450598 | P40: ASSTRA | R40: 9185119069 | S40: 45302 | V40: x | X40: Süden | Y40: Verladen | AA40: 45302 | AB40: 45302 | AC40: 0.52083333 | AD40: 0.53125 | AE40: 0.53472222 | AF40: 0.61458333 | AN40: =IF(AC40="","Kein Eintrag",IF(AD40="","Kein Eintrag",AD40-AC40)) -> 0.010416667 | AO40: =IF(AF40="","Kein Eintrag",IF(AD40="","Kein Eintrag",AF40-AD40)) -> 0.083333333 | AP40: =IF(AF40="","Kein Eintrag",IF(AC40="","Kein Eintrag",AF40-AC40)) -> 0.09375
...

Sheet Docs
A1: PO Number | B1: Datum | C1: Scan mit FI | D1: Scan per Mail | E1: Scan FI/COO/ATR | F1: Im Umschlag | G1: Verschickt mit Waybill No. | H1: Destination
A2: 4200203577 | B2: 45232 | H2: TR
A3: 4100038192 | B3: 45236 | H3: TR
A4: 4100038193 | B4: 45236 | H4: TR
A5: 4100038194 | B5: 45237 | H5: TR
A6: 4100038241 | B6: 45238 | H6: TR
A7: 4100038252 | B7: 45243 | H7: TR
A8: 4100038242 | B8: 45244 | H8: TR
A9: 4100038243 | B9: 45245 | H9: TR
A10: 4200208744 | B10: 45246 | H10: TR
A11: 4200210340 | B11: 45247 | H11: TR
A12: 4200210367 | B12: 45252 | H12: TR
A13: 4200210366 | B13: 45253 | H13: TR
... A15: 4100038599 | B15: 45257 | H15: TR
A16: 4100038291 | B16: 45278 | C16: x | D16: x | E16: x | F16: x | G16: 9768695930 | H16: TR
A17: 4100038290 | B17: 45278 | C17: x | D17: x | E17: x | F17: x | G17: 9768695930 | H17: TR
A18: 4100038299 | B18: 45278 | C18: x | D18: x | E18: x | F18: x | G18: 9768695930 | H18: TR
A19: 4100038298 | B19: 45280 | H19: TR
A20: 4100038292 | B20: 45281 | H20: TR
A21: 4200207906 | B21: 45232 | H21: TR
A22: 4200207917 | B22: 45233 | H22: TR
A23: 4200207908 | B23: 45236 | H23: TR
A24: 4200207910 | B24: 45237 | H24: TR
A25: 4200207918 | B25: 45237 | H25: TR
A26: 4200208358 | B26: 45238 | H26: TR
A27: 4200208359 | B27: 45238 | H27: TR
A28: 4200208360 | B28: 45239 | H28: TR
A29: 4200208361 | B29: 45240 | H29: TR
A30: 4200208362 | B30: 45240 | H30: TR
... A53: 4200208424 | B53: 45267 | H53: TR
A54: 4200208434 | B54: 45268 | C54: x | D54: x | E54: x | F54: x | G54: 9768695930 | H54: TR
A55: 4200208747 | B55: 45268 | H55: TR
A56: 4200208406 | B56: 45273 | C56: x | D56: x | E56: x | F56: x | G56: 9768695930 | H56: TR
A57: 4200208412 | B57: 45271 | C57: x | H57: TR
A58: 4200208414 | B58: 45272 | C58: x | D58: x | E58: x | F58: x | G58: 9768695930 | H58: TR
A59: 4200208415 | B59: 45272 | C59: x | D59: x | E59: x | F59: x | G59: 9768695930 | H59: TR
A60: 4200208416 | B60: 45273 | C60: x | D60: x | E60: x | F60: x | G60: 9768695930 | H60: TR
A61: 4200208417 | B61: 45273 | C61: x | D61: x | E61: x | F61: x | G61: 9768695930 | H61: TR
A62: 4200208418 | B62: 45275 | C62: x | D62: x | E62: x | F62: x | G62: 9768695930 | H62: TR
A63: 4200208419 | B63: 45274 | C63: x | D63: x | E63: x | F63: x | G63: 9768695930 | H63: TR
...

Sheet SFG_DDS
A1: DDS SFG Performance Tracker | G1: KW01 | M1: KW02 | T1: KW03 | AA1: KW04 | AH1: KW05 | AO1: KW06 | AV1: KW07 | BC1: KW08 | BJ1: KW09 | BQ1: KW10 | BX1: KW11 | CE1: KW12 | CL1: KW13 | CS1: KW14 | CZ1: KW15 | DG1: KW16 | DN1: KW17 | DU1: KW18 | EB1: KW19 | EI1: KW20 | EP1: KW21 | EW1: KW22 | FD1: KW23 | FK1: KW24 | FR1: KW25 | FY1: KW26 | GF1: KW27 | GM1: KW28 | GT1: KW29 | HA1: KW30 | HH1: KW31 | HO1: KW32 | HV1: KW33 | IC1: KW34 | IJ1: KW35 | IQ1: KW36 | IX1: KW37 | JE1: KW38 | JL1: KW39 | JS1: KW40 | JZ1: KW41 | KG1: KW42 | KN1: KW43 | KU1: KW44 | LB1: KW45 | LI1: KW46 | LP1: KW47 | LW1: KW48 | MD1: KW49 | MK1: KW50 | MR1: KW51 | MY1: KW52
C2: Limit/Target | D2: UoM | E2: Max. | F2: 44928 | G2: 44929 | H2: 44930 | I2: 44931 | J2: 44932 | K2: 44933 | L2: 44934 | M2: 44935 | N2: 44936 | O2: 44937 | P2: 44938 | Q2: 44939 | R2: 44940 | S2: 44941 | T2: 44942 | U2: 44943 | V2: 44944 | W2: 44945 | X2: 44946 | Y2: 44947 | Z2: 44948 | AA2: 44949 | AB2: 44950 | AC2: 44951 | AD2: 44952 | AE2: 44953 | AF2: 44954 | AG2: 44955 | AH2: 44956 | AI2: 44957 | AJ2: 44958 | AK2: 44959 | AL2: 44960 | AM2: 44961 | AN2: 44962 | AO2: 44963 | AP2: 44964 | AQ2: 44965 | AR2: 44966 | AS2: 44967 | AT2: 44968 | AU2: 44969 | AV2: 44970 | AW2: 44971 | AX2: 44972 | AY2: 44973 | AZ2: 44974 | BA2: 44975 | BB2: 44976 | BC2: 44977 | BD2: 44978 | BE2: 44979 | BF2: 44980 | BG2: 44981 | BH2: 44982 | BI2: 44983 | BJ2: 44984 | BK2: 44985 | BL2: 44986 | BM2: 44987 | BN2: 44988 | BO2: 44989 | BP2: 44990 | BQ2: 44991 | BR2: 44992 | BS2: 44993 | BT2: 44994 | BU2: 44995 | BV2: 44996 | BW2: 44997 | BX2: 44998 | BY2: 44999 | BZ2: 45000 | CA2: 45001 | CB2: 45002 | CC2: 45003 | CD2: 45004 | CE2: 45005 | CF2: 45006 | CG2: 45007 | CH2: 45008 | CI2: 45009 | CJ2: 45010 | CK2: 45011 | CL2: 45012 | CM2: 45013 | CN2: 45014 | CO2: 45015 | CP2: 45016 | CQ2: 45017 | CR2: 45018 | CS2: 45019 | CT2: 45020 | CU2: 45021 | CV2: 45022 | CW2: 45023 | CX2: 45024 | CY2: 45025 | CZ2: 45026 | DA2: 45027 | DB2: 45028 | DC2: 45029 | DD2: 45030 | DE2: 45031 | DF2: 45032 | DG2: 45033 | DH2: 45034 | DI2: 45035 | DJ2: 45036 | DK2: 45037 | DL2: 45038 | DM2: 45039 | DN2: 45040 | DO2: 45041 | DP2: 45042 | DQ2: 45043 | DR2: 45044 | DS2: 45045 | DT2: 45046 | DU2: 45047 | DV2: 45048 | DW2: 45049 | DX2: 45050 | DY2: 45051 | DZ2: 45052 | EA2: 45053 | EB2: 45054 | EC2: 45055 | ED2: 45056 | EE2: 45057 | EF2: 45058 | EG2: 45059 | EH2: 45060 | EI2: 45061 | EJ2: 45062 | EK2: 45063 | EL2: 45064 | EM2: 45065 | EN2: 45066 | EO2: 45067 | EP2: 45068 | EQ2: 45069 | ER2: 45070 | ES2: 45071 | ET2: 45072 | EU2: 45073 | EV2: 45074 | EW2: 45075 | EX2: 45076 | EY2: 45077 | EZ2: 45078 | FA2: 45079 | FB2: 45080 | FC2: 45081 | FD2: 45082 | FE2: 45083 | FF2: 45084 | FG2: 45085 | FH2: 45086 | FI2: 45087 | FJ2: 45088 | FK2: 45089 | FL2: 45090 | FM2: 45091 | FN2: 45092 | FO2: 45093 | FP2: 45094 | FQ2: 45095 | FR2: 45096 | FS2: 45097 | FT2: 45098 | FU2: 45099 | FV2: 45100 | FW2: 45101 | FX2: 45102 | FY2: 45103 | FZ2: 45104 | GA2: 45105 | GB2: 45106 | GC2: 45107 | GD2: 45108 | GE2: 45109 | GF2: 45110 | GG2: 45111 | GH2: 45112 | GI2: 45113 | GJ2: 45114 | GK2: 45115 | GL2: 45116 | GM2: 45117 | GN2: 45118 | GO2: 45119 | GP2: 45120 | GQ2: 45121 | GR2: 45122 | GS2: 45123 | GT2: 45124 | GU2: 45125 | GV2: 45126 | GW2: 45127 | GX2: 45128 | GY2: 45129 | GZ2: 45130 | HA2: 45131 | HB2: 45132 | HC2: 45133 | HD2: 45134 | HE2: 45135 | HF2: 45136 | HG2: 45137 | HH2: 45138 | HI2: 45139 | HJ2: 45140 | HK2: 45141 | HL2: 45142 | HM2: 45143 | HN2: 45144 | HO2: 45145 | HP2: 45146 | HQ2: 45147 | HR2: 45148 | HS2: 45149 | HT2: 45150 | HU2: 45151 | HV2: 45152 | HW2: 45153 | HX2: 45154 | HY2: 45155 | HZ2: 45156 | IA2: 45157 | IB2: 45158 | IC2: 45159 | ID2: 45160 | IE2: 45161 | IF2: 45162 | IG2: 45163 | IH2: 45164 | II2: 45165 | IJ2: 45166 | IK2: 45167 | IL2: 45168 | IM2: 45169 | IN2: 45170 | IO2: 45171 | IP2: 45172 | IQ2: 45173 | IR2: 45174 | IS2: 45175 | IT2: 45176 | IU2: 45177 | IV2: 45178 | IW2: 45179 | IX2: 45180 | IY2: 45181 | IZ2: 45182 | JA2: 45183 | JB2: 45184 | JC2: 45185 | JD2: 45186 | JE2: 45187 | JF2: 45188 | JG2: 45189 | JH2: 45190 | JI2: 45191 | JJ2: 45192 | JK2: 45193 | JL2: 45194 | JM2: 45195 | JN2: 45196 | JO2: 45197 | JP2: 45198 | JQ2: 45199 | JR2: 45200 | JS2: 45201 | JT2: 45202 | JU2: 45203 | JV2: 45204 | JW2: 45205 | JX2: 45206 | JY2: 45207 | JZ2: 45208 | KA2: 45209 | KB2: 45210 | KC2: 45211 | KD2: 45212 | KE2: 45213 | KF2: 45214 | KG2: 45215 | KH2: 45216 | KI2: 45217 | KJ2: 45218 | KK2: 45219 | KL2: 45220 | KM2: 45221 | KN2: 45222 | KO2: 45223 | KP2: 45224 | KQ2: 45225 | KR2: 45226 | KS2: 45227 | KT2: 45228 | KU2: 45229 | KV2: 45230 | KW2: 45231 | KX2: 45232 | KY2: 45233 | KZ2: 45234 | LA2: 45235 | LB2: 45236 | LC2: 45237 | LD2: 45238 | LE2: 45239 | LF2: 45240 | LG2: 45241 | LH2: 45242 | LI2: 45243 | LJ2: 45244 | LK2: 45245 | LL2: 45246 | LM2: 45247 | LN2: 45248 | LO2: 45249 | LP2: 45250 | LQ2: 45251 | LR2: 45252 | LS2: 45253 | LT2: 45254 | LU2: 45255 | LV2: 45256 | LW2: 45257 | LX2: 45258 | LY2: 45259 | LZ2: 45260 | MA2: 45261 | MB2: 45262 | MC2: 45263 | MD2: 45264 | ME2: 45265 | MF2: 45266 | MG2: 45267 | MH2: 45268 | MI2: 45269 | MJ2: 45270 | MK2: 45271 | ML2: 45272 | MM2: 45273 | MN2: 45274 | MO2: 45275 | MP2: 45276 | MQ2: 45277 | MR2: 45278 | MS2: 45279 | MT2: 45280 | MU2: 45281 | MV2: 45282 | MW2: 45283 | MX2: 45284 | MY2: 45285 | MZ2: 45286 | NA2: 45287 | NB2: 45288 | NC2: 45289 | ND2: 45290 | NE2: 45291
